Workbook

Sheet AND
D1: Acrónimo | E1: AFI | F1: IAS | G1: ICM | H1: IPI | I1: PER | J1: GAS | K1: HIP | L1: IPC | M1: AFIE | N1: PIB | O1: PIB_CCAA
D2: SA | E2: 0 | F2: 0 | G2: 0 | H2: 0 | I2: 0 | J2: 0 | K2: 0 | L2: 0 | M2: 0 | N2: 0 | O2: 0
D3: DEF | E3: 1 | F3: 1 | G3: 1 | H3: 1 | I3: 1 | J3: 1 | K3: 1 | L3: 1 | M3: 1 | N3: 1 | O3: 1
D4: Serie | E4: afiliados | F4: creditos | G4: depositos | H4: consumo productos petro | I4: hipotecas | J4: indice actividad serviciios | K4: indice comercio al por menor | L4: indice comercio al por menor | M4: indice comercio al por menor | N4: PIB ESPAÑA | O4: PIB ccaa
D5: Enlaces y Deflactores
D6: Fecha INI MOD | E6: 34700 | F6: 34700 | G6: 34700 | H6: 34731 | I6: 34759 | J6: 34790 | K6: 34820 | L6: 34851 | M6: 34881 | N6: 34973 | O6: 35004
D7: Cod | E7: SC | F7: 190000m | G7: 229000cc.d | H7: 229000cc.d | I7: 229000cc.d | J7: 229000cc.d | K7: 229000cc.d | L7: 229000cc.d | M7: 229000cc.d | N7: 229000cc.d | O7: 229000cc.d
D8: Año | E8: 1995 | F8: 2005 | G8: 2001 | H8: 1995 | I8: 1995 | J8: 1997 | K8: 1995 | L8: 1995 | M8: 1995 | N8: 1995 | O8: 2000
D9: Freq | E9: 12 | F9: 12 | G9: 12 | H9: 12 | I9: 12 | J9: 12 | K9: 12 | L9: 12 | M9: 12 | N9: 4 | O9: 1
D10: Mes INI | E10: 8 | F10: 1 | G10: 1 | H10: 1 | I10: 1 | J10: 1 | K10: 1 | L10: 1 | M10: 1 | N10: 1 | O10: 0
D11: type | E11: 6 | F11: 6 | G11: 6 | H11: 6 | I11: 6 | J11: 6 | K11: 6 | L11: 6 | M11: 6 | N11: 2 | O11: 1
D12: dlg | E12: 1 | F12: 1 | G12: 1 | H12: 1 | I12: 1 | J12: 1 | K12: 1 | L12: 1 | M12: 1 | N12: 1 | O12: 1
D13: selector | E13: 1 | F13: 1 | G13: 1 | H13: 1 | I13: 1 | J13: 1 | K13: 1 | L13: 1 | M13: 1 | N13: 1 | O13: 1
A14: Posición de outlier---> | D14: outliers | E14: 0 | F14: 0 | G14: 0 | H14: 0 | I14: 0 | J14: 0 | K14: 0 | L14: 0 | M14: 0 | N14: 0 | O14: 0
A15: =VALUE("1/"&C15&"/"&B15) -> 34700 | B15: =LEFT(D15,4) -> 1995 | C15: 1 | D15: 199501 | E15: =+IF([3]AND!B2="","",[3]AND!B2) -> 1859111.6 | F15: =+IF([3]AND!C2="","",[3]AND!C2) | G15: =+IF([3]AND!D2="","",[3]AND!D2) | H15: =+IF([3]AND!E2="","",[3]AND!E2) -> 122.24661 | I15: =+IF([3]AND!F2="","",[3]AND!F2) -> 1291490.8 | J15: =+IF([3]AND!G2="","",[3]AND!G2) | K15: =+IF([3]AND!H2="","",[3]AND!H2) -> 8540.5637 | L15: =+IF([3]AND!I2="","",[3]AND!I2) -> 59.083898 | M15: =+IF([3]AND!J2="","",[3]AND!J2) -> 1859111.6 | N15: =+'[1]Trim CM INICIAL_ECM'!J4 -> 67.016017 | O15: =+[2]anu!B2 -> 84.237632 | P15: 199501 | Q15: 2000
A16: =VALUE("1/"&C16&"/"&B16) -> 34731 | B16: =LEFT(D16,4) -> 1995 | C16: 2 | D16: 199502 | E16: =+IF([3]AND!B3="","",[3]AND!B3) -> 1884224.4 | F16: =+IF([3]AND!C3="","",[3]AND!C3) | G16: =+IF([3]AND!D3="","",[3]AND!D3) | H16: =+IF([3]AND!E3="","",[3]AND!E3) -> 108.07818 | I16: =+IF([3]AND!F3="","",[3]AND!F3) -> 1484572.9 | J16: =+IF([3]AND!G3="","",[3]AND!G3) | K16: =+IF([3]AND!H3="","",[3]AND!H3) -> 7140.6572 | L16: =+IF([3]AND!I3="","",[3]AND!I3) -> 59.556569 | M16: =+IF([3]AND!J3="","",[3]AND!J3) -> 1884224.4 | N16: =+'[1]Trim CM INICIAL_ECM'!J5 -> 67.457788 | O16: =+[2]anu!B3 -> 87.471178 | P16: 199502 | Q16: =+Q15+1 -> 2001
A17: =VALUE("1/"&C17&"/"&B17) -> 34759 | B17: =LEFT(D17,4) -> 1995 | C17: 3 | D17: 199503 | E17: =+IF([3]AND!B4="","",[3]AND!B4) -> 1905549.4 | F17: =+IF([3]AND!C4="","",[3]AND!C4) | G17: =+IF([3]AND!D4="","",[3]AND!D4) | H17: =+IF([3]AND!E4="","",[3]AND!E4) -> 117.19465 | I17: =+IF([3]AND!F4="","",[3]AND!F4) -> 2046164.6 | J17: =+IF([3]AND!G4="","",[3]AND!G4) | K17: =+IF([3]AND!H4="","",[3]AND!H4) -> 6976.8518 | L17: =+IF([3]AND!I4="","",[3]AND!I4) -> 59.973465 | M17: =+IF([3]AND!J4="","",[3]AND!J4) -> 1905549.4 | N17: =+'[1]Trim CM INICIAL_ECM'!J6 -> 67.756519 | O17: =+[2]anu!B4 -> 90.579301 | P17: 199503 | Q17: =+Q16+1 -> 2002
A18: =VALUE("1/"&C18&"/"&B18) -> 34790 | B18: =LEFT(D18,4) -> 1995 | C18: 4 | D18: 199504 | E18: =+IF([3]AND!B5="","",[3]AND!B5) -> 1902587.7 | F18: =+IF([3]AND!C5="","",[3]AND!C5) | G18: =+IF([3]AND!D5="","",[3]AND!D5) | H18: =+IF([3]AND!E5="","",[3]AND!E5) -> 100.38958 | I18: =+IF([3]AND!F5="","",[3]AND!F5) -> 2906228.8 | J18: =+IF([3]AND!G5="","",[3]AND!G5) | K18: =+IF([3]AND!H5="","",[3]AND!H5) -> 6275.0084 | L18: =+IF([3]AND!I5="","",[3]AND!I5) -> 60.213359 | M18: =+IF([3]AND!J5="","",[3]AND!J5) -> 1902587.7 | N18: =+'[1]Trim CM INICIAL_ECM'!J7 -> 68.269558 | O18: =+[2]anu!B5 -> 94.186666 | P18: 199504 | Q18: =+Q17+1 -> 2003
A19: =VALUE("1/"&C19&"/"&B19) -> 34820 | B19: =LEFT(D19,4) -> 1995 | C19: 5 | D19: 199505 | E19: =+IF([3]AND!B6="","",[3]AND!B6) -> 1925416.2 | F19: =+IF([3]AND!C6="","",[3]AND!C6) | G19: =+IF([3]AND!D6="","",[3]AND!D6) | H19: =+IF([3]AND!E6="","",[3]AND!E6) -> 114.55809 | I19: =+IF([3]AND!F6="","",[3]AND!F6) -> 2807682.3 | J19: =+IF([3]AND!G6="","",[3]AND!G6) | K19: =+IF([3]AND!H6="","",[3]AND!H6) -> 7039.8538 | L19: =+IF([3]AND!I6="","",[3]AND!I6) -> 60.092933 | M19: =+IF([3]AND!J6="","",[3]AND!J6) -> 1925416.2 | N19: =+'[1]Trim CM INICIAL_ECM'!J8 -> 68.661842 | O19: =+[2]anu!B6 -> 97.421534 | P19: 199601 | Q19: =+Q18+1 -> 2004
A20: =VALUE("1/"&C20&"/"&B20) -> 34851 | B20: =LEFT(D20,4) -> 1995 | C20: 6 | D20: 199506 | E20: =+IF([3]AND!B7="","",[3]AND!B7) -> 1943276.3 | F20: =+IF([3]AND!C7="","",[3]AND!C7) | G20: =+IF([3]AND!D7="","",[3]AND!D7) | H20: =+IF([3]AND!E7="","",[3]AND!E7) -> 119.06164 | I20: =+IF([3]AND!F7="","",[3]AND!F7) -> 2656808.9 | J20: =+IF([3]AND!G7="","",[3]AND!G7) | K20: =+IF([3]AND!H7="","",[3]AND!H7) -> 6558.5179 | L20: =+IF([3]AND!I7="","",[3]AND!I7) -> 60.153025 | M20: =+IF([3]AND!J7="","",[3]AND!J7) -> 1943276.3 | N20: =+'[1]Trim CM INICIAL_ECM'!J9 -> 69.136714 | O20: =+[2]anu!B7 -> 100.69843 | P20: 199602 | Q20: =+Q19+1 -> 2005
A21: =VALUE("1/"&C21&"/"&B21) -> 34881 | B21: =LEFT(D21,4) -> 1995 | C21: 7 | D21: 199507 | E21: =+IF([3]AND!B8="","",[3]AND!B8) -> 1947465.8 | F21: =+IF([3]AND!C8="","",[3]AND!C8) | G21: =+IF([3]AND!D8="","",[3]AND!D8) | H21: =+IF([3]AND!E8="","",[3]AND!E8) -> 109.06654 | I21: =+IF([3]AND!F8="","",[3]AND!F8) -> 3130417.4 | J21: =+IF([3]AND!G8="","",[3]AND!G8) | K21: =+IF([3]AND!H8="","",[3]AND!H8) -> 5506.3829 | L21: =+IF([3]AND!I8="","",[3]AND!I8) -> 60.092872 | M21: =+IF([3]AND!J8="","",[3]AND!J8) -> 1947465.8 | N21: =+'[1]Trim CM INICIAL_ECM'!J10 -> 69.703856 | O21: =+[2]anu!B8 -> 104.7389 | P21: 199603 | Q21: =+Q20+1 -> 2006
A22: =VALUE("1/"&C22&"/"&B22) -> 34912 | B22: =LEFT(D22,4) -> 1995 | C22: 8 | D22: 199508 | E22: =+IF([3]AND!B9="","",[3]AND!B9) -> 1948982.1 | F22: =+IF([3]AND!C9="","",[3]AND!C9) | G22: =+IF([3]AND!D9="","",[3]AND!D9) | H22: =+IF([3]AND!E9="","",[3]AND!E9) -> 78.752051 | I22: =+IF([3]AND!F9="","",[3]AND!F9) -> 3600674.9 | J22: =+IF([3]AND!G9="","",[3]AND!G9) | K22: =+IF([3]AND!H9="","",[3]AND!H9) -> 5314.8565 | L22: =+IF([3]AND!I9="","",[3]AND!I9) -> 60.273151 | M22: =+IF([3]AND!J9="","",[3]AND!J9) -> 1948982.1 | N22: =+'[1]Trim CM INICIAL_ECM'!J11 -> 70.050606 | O22: =+[2]anu!B9 -> 108.3741 | P22: 199604 | Q22: =+Q21+1 -> 2007
A23: =VALUE("1/"&C23&"/"&B23) -> 34943 | B23: =LEFT(D23,4) -> 1995 | C23: 9 | D23: 199509 | E23: =+IF([3]AND!B10="","",[3]AND!B10) -> 1935634.8 | F23: =+IF([3]AND!C10="","",[3]AND!C10) | G23: =+IF([3]AND!D10="","",[3]AND!D10) | H23: =+IF([3]AND!E10="","",[3]AND!E10) -> 109.72577 | I23: =+IF([3]AND!F10="","",[3]AND!F10) -> 3121260.4 | J23: =+IF([3]AND!G10="","",[3]AND!G10) | K23: =+IF([3]AND!H10="","",[3]AND!H10) -> 6080.962 | L23: =+IF([3]AND!I10="","",[3]AND!I10) -> 60.393697 | M23: =+IF([3]AND!J10="","",[3]AND!J10) -> 1935634.8 | N23: =+'[1]Trim CM INICIAL_ECM'!J12 -> 70.749209 | O23: =+[2]anu!B10 -> 108.48215 | P23: 199701 | Q23: =+Q22+1 -> 2008
A24: =VALUE("1/"&C24&"/"&B24) -> 34973 | B24: =LEFT(D24,4) -> 1995 | C24: 10 | D24: 199510 | E24: =+IF([3]AND!B11="","",[3]AND!B11) -> 1921734.9 | F24: =+IF([3]AND!C11="","",[3]AND!C11) | G24: =+IF([3]AND!D11="","",[3]AND!D11) | H24: =+IF([3]AND!E11="","",[3]AND!E11) -> 115.32716 | I24: =+IF([3]AND!F11="","",[3]AND!F11) -> 2577410 | J24: =+IF([3]AND!G11="","",[3]AND!G11) | K24: =+IF([3]AND!H11="","",[3]AND!H11) -> 5324.9369 | L24: =+IF([3]AND!I11="","",[3]AND!I11) -> 60.454091 | M24: =+IF([3]AND!J11="","",[3]AND!J11) -> 1921734.9 | N24: =+'[1]Trim CM INICIAL_ECM'!J13 -> 71.387254 | O24: =+[2]anu!B11 -> 104.02309 | P24: 199702 | Q24: =+Q23+1 -> 2009
A25: =VALUE("1/"&C25&"/"&B25) -> 35004 | B25: =LEFT(D25,4) -> 1995 | C25: 11 | D25: 199511 | E25: =+IF([3]AND!B12="","",[3]AND!B12) -> 1930784.3 | F25: =+IF([3]AND!C12="","",[3]AND!C12) | G25: =+IF([3]AND!D12="","",[3]AND!D12) | H25: =+IF([3]AND!E12="","",[3]AND!E12) -> 117.52375 | I25: =+IF([3]AND!F12="","",[3]AND!F12) -> 1619775.2 | J25: =+IF([3]AND!G12="","",[3]AND!G12) | K25: =+IF([3]AND!H12="","",[3]AND!H12) -> 5681.5287 | L25: =+IF([3]AND!I12="","",[3]AND!I12) -> 60.756362 | M25: =+IF([3]AND!J12="","",[3]AND!J12) -> 1930784.3 | N25: =+'[1]Trim CM INICIAL_ECM'!J14 -> 72.179702 | O25: =+[2]anu!B12 -> 102.64082 | P25: 199703 | Q25: =+Q24+1 -> 2010
A26: =VALUE("1/"&C26&"/"&B26) -> 35034 | B26: =LEFT(D26,4) -> 1995 | C26: 12 | D26: 199512 | E26: =+IF([3]AND!B13="","",[3]AND!B13) -> 1936048.2 | F26: =+IF([3]AND!C13="","",[3]AND!C13) | G26: =+IF([3]AND!D13="","",[3]AND!D13) | H26: =+IF([3]AND!E13="","",[3]AND!E13) -> 106.97918 | I26: =+IF([3]AND!F13="","",[3]AND!F13) -> 1548418 | J26: =+IF([3]AND!G13="","",[3]AND!G13) | K26: =+IF([3]AND!H13="","",[3]AND!H13) -> 4750.3578 | L26: =+IF([3]AND!I13="","",[3]AND!I13) -> 60.999387 | M26: =+IF([3]AND!J13="","",[3]AND!J13) -> 1936048.2 | N26: =+'[1]Trim CM INICIAL_ECM'!J15 -> 73.193535 | O26: =+[2]anu!B13 -> 102.3609 | P26: 199704 | Q26: =+Q25+1 -> 2011
A27: =VALUE("1/"&C27&"/"&B27) -> 35065 | B27: =LEFT(D27,4) -> 1996 | C27: 1 | D27: 199601 | E27: =+IF([3]AND!B14="","",[3]AND!B14) -> 1880054.6 | F27: =+IF([3]AND!C14="","",[3]AND!C14) | G27: =+IF([3]AND!D14="","",[3]AND!D14) | H27: =+IF([3]AND!E14="","",[3]AND!E14) -> 109.17622 | I27: =+IF([3]AND!F14="","",[3]AND!F14) -> 1357015.1 | J27: =+IF([3]AND!G14="","",[3]AND!G14) | K27: =+IF([3]AND!H14="","",[3]AND!H14) -> 7524.97 | L27: =+IF([3]AND!I14="","",[3]AND!I14) -> 61.426383 | M27: =+IF([3]AND!J14="","",[3]AND!J14) -> 1880054.6 | N27: =+'[1]Trim CM INICIAL_ECM'!J16 -> 73.809914 | O27: =+[2]anu!B14 -> 98.790917 | P27: 199801 | Q27: =+Q26+1 -> 2012
... A45: =VALUE("1/"&C45&"/"&B45) -> 35612 | B45: =LEFT(D45,4) -> 1997 | C45: 7 | D45: 199707 | E45: =+IF([3]AND!B32="","",[3]AND!B32) -> 2072137.8 | F45: =+IF([3]AND!C32="","",[3]AND!C32) | G45: =+IF([3]AND!D32="","",[3]AND!D32) | H45: =+IF([3]AND!E32="","",[3]AND!E32) -> 121.58778 | I45: =+IF([3]AND!F32="","",[3]AND!F32) -> 3680765.8 | J45: =+IF([3]AND!G32="","",[3]AND!G32) -> 282512 | K45: =+IF([3]AND!H32="","",[3]AND!H32) -> 7590.4921 | L45: =+IF([3]AND!I32="","",[3]AND!I32) -> 63.166785 | M45: =+IF([3]AND!J32="","",[3]AND!J32) -> 2072137.8 | N45: =+'[1]Trim CM INICIAL_ECM'!J34 -> 88.1866 | O45: =+[2]anu!B32 -> 133.35611 | P45: 200203 | Q45: =+Q44+1 -> 2030
A46: =VALUE("1/"&C46&"/"&B46) -> 35643 | B46: =LEFT(D46,4) -> 1997 | C46: 8 | D46: 199708 | E46: =+IF([3]AND!B33="","",[3]AND!B33) -> 2071293.3 | F46: =+IF([3]AND!C33="","",[3]AND!C33) | G46: =+IF([3]AND!D33="","",[3]AND!D33) | H46: =+IF([3]AND!E33="","",[3]AND!E33) -> 83.804483 | I46: =+IF([3]AND!F33="","",[3]AND!F33) -> 4576594.6 | J46: =+IF([3]AND!G33="","",[3]AND!G33) -> 263721 | K46: =+IF([3]AND!H33="","",[3]AND!H33) -> 6064.5814 | L46: =+IF([3]AND!I33="","",[3]AND!I33) -> 63.356286 | M46: =+IF([3]AND!J33="","",[3]AND!J33) -> 2071293.3 | N46: =+'[1]Trim CM INICIAL_ECM'!J35 -> 88.87513 | P46: 200204
A47: =VALUE("1/"&C47&"/"&B47) -> 35674 | B47: =LEFT(D47,4) -> 1997 | C47: 9 | D47: 199709 | E47: =+IF([3]AND!B34="","",[3]AND!B34) -> 2058910.4 | F47: =+IF([3]AND!C34="","",[3]AND!C34) | G47: =+IF([3]AND!D34="","",[3]AND!D34) | H47: =+IF([3]AND!E34="","",[3]AND!E34) -> 117.30442 | I47: =+IF([3]AND!F34="","",[3]AND!F34) -> 3723917.9 | J47: =+IF([3]AND!G34="","",[3]AND!G34) -> 269473 | K47: =+IF([3]AND!H34="","",[3]AND!H34) -> 7233.9003 | L47: =+IF([3]AND!I34="","",[3]AND!I34) -> 63.736423 | M47: =+IF([3]AND!J34="","",[3]AND!J34) -> 2058910.4 | N47: =+'[1]Trim CM INICIAL_ECM'!J36 -> 89.731812 | P47: 200301
A48: =VALUE("1/"&C48&"/"&B48) -> 35704 | B48: =LEFT(D48,4) -> 1997 | C48: 10 | D48: 199710 | E48: =+IF([3]AND!B35="","",[3]AND!B35) -> 2057184.5 | F48: =+IF([3]AND!C35="","",[3]AND!C35) | G48: =+IF([3]AND!D35="","",[3]AND!D35) | H48: =+IF([3]AND!E35="","",[3]AND!E35) -> 128.28774 | I48: =+IF([3]AND!F35="","",[3]AND!F35) -> 3038328.5 | J48: =+IF([3]AND!G35="","",[3]AND!G35) -> 297358 | K48: =+IF([3]AND!H35="","",[3]AND!H35) -> 9094.9821 | L48: =+IF([3]AND!I35="","",[3]AND!I35) -> 63.672687 | M48: =+IF([3]AND!J35="","",[3]AND!J35) -> 2057184.5 | N48: =+'[1]Trim CM INICIAL_ECM'!J37 -> 90.07568 | P48: 200302
A49: =VALUE("1/"&C49&"/"&B49) -> 35735 | B49: =LEFT(D49,4) -> 1997 | C49: 11 | D49: 199711 | E49: =+IF([3]AND!B36="","",[3]AND!B36) -> 2065999.6 | F49: =+IF([3]AND!C36="","",[3]AND!C36) | G49: =+IF([3]AND!D36="","",[3]AND!D36) | H49: =+IF([3]AND!E36="","",[3]AND!E36) -> 120.37947 | I49: =+IF([3]AND!F36="","",[3]AND!F36) -> 1898279.1 | J49: =+IF([3]AND!G36="","",[3]AND!G36) -> 239751 | K49: =+IF([3]AND!H36="","",[3]AND!H36) -> 7556.471 | L49: =+IF([3]AND!I36="","",[3]AND!I36) -> 63.73636 | M49: =+IF([3]AND!J36="","",[3]AND!J36) -> 2065999.6 | N49: =+'[1]Trim CM INICIAL_ECM'!J38 -> 90.746529 | P49: 200303
A50: =VALUE("1/"&C50&"/"&B50) -> 35765 | B50: =LEFT(D50,4) -> 1997 | C50: 12 | D50: 199712 | E50: =+IF([3]AND!B37="","",[3]AND!B37) -> 2053932.2 | F50: =+IF([3]AND!C37="","",[3]AND!C37) | G50: =+IF([3]AND!D37="","",[3]AND!D37) | H50: =+IF([3]AND!E37="","",[3]AND!E37) -> 122.4659 | I50: =+IF([3]AND!F37="","",[3]AND!F37) -> 1699282.9 | J50: =+IF([3]AND!G37="","",[3]AND!G37) -> 267352 | K50: =+IF([3]AND!H37="","",[3]AND!H37) -> 7121.7566 | L50: =+IF([3]AND!I37="","",[3]AND!I37) -> 63.800096 | M50: =+IF([3]AND!J37="","",[3]AND!J37) -> 2053932.2 | N50: =+'[1]Trim CM INICIAL_ECM'!J39 -> 91.507449 | P50: 200304
A51: =VALUE("1/"&C51&"/"&B51) -> 35796 | B51: =LEFT(D51,4) -> 1998 | C51: 1 | D51: 199801 | E51: =+IF([3]AND!B38="","",[3]AND!B38) -> 2024070.4 | F51: =+IF([3]AND!C38="","",[3]AND!C38) | G51: =+IF([3]AND!D38="","",[3]AND!D38) | H51: =+IF([3]AND!E38="","",[3]AND!E38) -> 138.06289 | I51: =+IF([3]AND!F38="","",[3]AND!F38) -> 1679090.3 | J51: =+IF([3]AND!G38="","",[3]AND!G38) -> 255134 | K51: =+IF([3]AND!H38="","",[3]AND!H38) -> 10119.396 | L51: =+IF([3]AND!I38="","",[3]AND!I38) -> 63.927696 | M51: =+IF([3]AND!J38="","",[3]AND!J38) -> 2024070.4 | N51: =+'[1]Trim CM INICIAL_ECM'!J40 -> 92.042783 | P51: 200401
A52: =VALUE("1/"&C52&"/"&B52) -> 35827 | B52: =LEFT(D52,4) -> 1998 | C52: 2 | D52: 199802 | E52: =+IF([3]AND!B39="","",[3]AND!B39) -> 2064655.6 | F52: =+IF([3]AND!C39="","",[3]AND!C39) | G52: =+IF([3]AND!D39="","",[3]AND!D39) | H52: =+IF([3]AND!E39="","",[3]AND!E39) -> 129.05677 | I52: =+IF([3]AND!F39="","",[3]AND!F39) -> 1984333.5 | J52: =+IF([3]AND!G39="","",[3]AND!G39) -> 244785 | K52: =+IF([3]AND!H39="","",[3]AND!H39) -> 8713.1894 | L52: =+IF([3]AND!I39="","",[3]AND!I39) -> 63.927696 | M52: =+IF([3]AND!J39="","",[3]AND!J39) -> 2064655.6 | N52: =+'[1]Trim CM INICIAL_ECM'!J41 -> 93.020239 | P52: 200402
A53: =VALUE("1/"&C53&"/"&B53) -> 35855 | B53: =LEFT(D53,4) -> 1998 | C53: 3 | D53: 199803 | E53: =+IF([3]AND!B40="","",[3]AND!B40) -> 2102584.4 | F53: =+IF([3]AND!C40="","",[3]AND!C40) | G53: =+IF([3]AND!D40="","",[3]AND!D40) | H53: =+IF([3]AND!E40="","",[3]AND!E40) -> 126.97003 | I53: =+IF([3]AND!F40="","",[3]AND!F40) -> 2670101.6 | J53: =+IF([3]AND!G40="","",[3]AND!G40) -> 306659 | K53: =+IF([3]AND!H40="","",[3]AND!H40) -> 8899.6756 | L53: =+IF([3]AND!I40="","",[3]AND!I40) -> 63.927696 | M53: =+IF([3]AND!J40="","",[3]AND!J40) -> 2102584.4 | N53: =+'[1]Trim CM INICIAL_ECM'!J42 -> 93.804639 | P53: 200403
A54: =VALUE("1/"&C54&"/"&B54) -> 35886 | B54: =LEFT(D54,4) -> 1998 | C54: 4 | D54: 199804 | E54: =+IF([3]AND!B41="","",[3]AND!B41) -> 2117115 | F54: =+IF([3]AND!C41="","",[3]AND!C41) | G54: =+IF([3]AND!D41="","",[3]AND!D41) | H54: =+IF([3]AND!E41="","",[3]AND!E41) -> 113.35016 | I54: =+IF([3]AND!F41="","",[3]AND!F41) -> 3461115 | J54: =+IF([3]AND!G41="","",[3]AND!G41) -> 293442 | K54: =+IF([3]AND!H41="","",[3]AND!H41) -> 8551.9041 | L54: =+IF([3]AND!I41="","",[3]AND!I41) -> 63.991624 | M54: =+IF([3]AND!J41="","",[3]AND!J41) -> 2117115 | N54: =+'[1]Trim CM INICIAL_ECM'!J43 -> 94.47041 | P54: 200404
A55: =VALUE("1/"&C55&"/"&B55) -> 35916 | B55: =LEFT(D55,4) -> 1998 | C55: 5 | D55: 199805 | E55: =+IF([3]AND!B42="","",[3]AND!B42) -> 2143782.2 | F55: =+IF([3]AND!C42="","",[3]AND!C42) | G55: =+IF([3]AND!D42="","",[3]AND!D42) | H55: =+IF([3]AND!E42="","",[3]AND!E42) -> 116.31545 | I55: =+IF([3]AND!F42="","",[3]AND!F42) -> 3454882.2 | J55: =+IF([3]AND!G42="","",[3]AND!G42) -> 278168 | K55: =+IF([3]AND!H42="","",[3]AND!H42) -> 7940.7838 | L55: =+IF([3]AND!I42="","",[3]AND!I42) -> 63.991624 | M55: =+IF([3]AND!J42="","",[3]AND!J42) -> 2143782.2 | N55: =+'[1]Trim CM INICIAL_ECM'!J44 -> 95.314485 | P55: 200501
A56: =VALUE("1/"&C56&"/"&B56) -> 35947 | B56: =LEFT(D56,4) -> 1998 | C56: 6 | D56: 199806 | E56: =+IF([3]AND!B43="","",[3]AND!B43) -> 2174453.4 | F56: =+IF([3]AND!C43="","",[3]AND!C43) | G56: =+IF([3]AND!D43="","",[3]AND!D43) | H56: =+IF([3]AND!E43="","",[3]AND!E43) -> 123.78457 | I56: =+IF([3]AND!F43="","",[3]AND!F43) -> 3342827.1 | J56: =+IF([3]AND!G43="","",[3]AND!G43) -> 300222 | K56: =+IF([3]AND!H43="","",[3]AND!H43) -> 8183.9718 | L56: =+IF([3]AND!I43="","",[3]AND!I43) -> 64.055615 | M56: =+IF([3]AND!J43="","",[3]AND!J43) -> 2174453.4 | N56: =+'[1]Trim CM INICIAL_ECM'!J45 -> 96.160515 | P56: 200502
A57: =VALUE("1/"&C57&"/"&B57) -> 35977 | B57: =LEFT(D57,4) -> 1998 | C57: 7 | D57: 199807 | E57: =+IF([3]AND!B44="","",[3]AND!B44) -> 2176021.4 | F57: =+IF([3]AND!C44="","",[3]AND!C44) | G57: =+IF([3]AND!D44="","",[3]AND!D44) | H57: =+IF([3]AND!E44="","",[3]AND!E44) -> 126.85988 | I57: =+IF([3]AND!F44="","",[3]AND!F44) -> 4069204.5 | J57: =+IF([3]AND!G44="","",[3]AND!G44) -> 326813 | K57: =+IF([3]AND!H44="","",[3]AND!H44) -> 8330.1367 | L57: =+IF([3]AND!I44="","",[3]AND!I44) -> 64.247782 | M57: =+IF([3]AND!J44="","",[3]AND!J44) -> 2176021.4 | N57: =+'[1]Trim CM INICIAL_ECM'!J46 -> 97.081208 | P57: 200503
...

Sheet ARA
D1: Acrónimo | E1: AFI | F1: IAS | G1: ICM | H1: IPI | I1: PER | J1: GAS | K1: HIP | L1: IPC | M1: AFIE | N1: PIB | O1: PIB_CCAA
D2: SA | E2: 0 | F2: 0 | G2: 0 | H2: 0 | I2: 0 | J2: 0 | K2: 0 | L2: 0 | M2: 0 | N2: 0 | O2: 0
D3: DEF | E3: 1 | F3: 1 | G3: 1 | H3: 1 | I3: 1 | J3: 1 | K3: 1 | L3: 1 | M3: 1 | N3: 1 | O3: 1
D4: Serie | E4: afiliados | F4: creditos | G4: depositos | H4: consumo productos petro | I4: hipotecas | J4: indice actividad serviciios | K4: indice comercio al por menor | L4: indice comercio al por menor | M4: indice comercio al por menor | N4: PIB ESPAÑA | O4: PIB ccaa
D5: Enlaces y Deflactores
D6: Fecha INI MOD | E6: 34700 | F6: 34700 | G6: 34700 | H6: 34731 | I6: 34759 | J6: 34790 | K6: 34820 | L6: 34851 | M6: 34881 | N6: 34973 | O6: 35004
D7: Cod | E7: SC | F7: 190000m | G7: 229000cc.d | H7: 229000cc.d | I7: 229000cc.d | J7: 229000cc.d | K7: 229000cc.d | L7: 229000cc.d | M7: 229000cc.d | N7: 229000cc.d | O7: 229000cc.d
D8: Año | E8: 1995 | F8: 2005 | G8: 2001 | H8: 1995 | I8: 1995 | J8: 1997 | K8: 1995 | L8: 1995 | M8: 1995 | N8: 1995 | O8: 2000
D9: Freq | E9: 12 | F9: 12 | G9: 12 | H9: 12 | I9: 12 | J9: 12 | K9: 12 | L9: 12 | M9: 12 | N9: 4 | O9: 1
D10: Mes INI | E10: 8 | F10: 1 | G10: 1 | H10: 1 | I10: 1 | J10: 1 | K10: 1 | L10: 1 | M10: 1 | N10: 1 | O10: 0
D11: type | E11: 6 | F11: 6 | G11: 6 | H11: 6 | I11: 6 | J11: 6 | K11: 6 | L11: 6 | M11: 6 | N11: 2 | O11: 1
D12: dlg | E12: 1 | F12: 1 | G12: 1 | H12: 1 | I12: 1 | J12: 1 | K12: 1 | L12: 1 | M12: 1 | N12: 1 | O12: 1
D13: selector | E13: =+AND!E13 -> 1 | F13: =+AND!F13 -> 1 | G13: =+AND!G13 -> 1 | H13: =+AND!H13 -> 1 | I13: =+AND!I13 -> 1 | J13: =+AND!J13 -> 1 | K13: =+AND!K13 -> 1 | L13: =+AND!L13 -> 1 | ... O13: =+AND!O13 -> 1
A14: Posición de outlier---> | D14: outliers | E14: 0 | F14: 0 | G14: 0 | H14: 0 | I14: 0 | J14: 0 | K14: 0 | L14: 0 | M14: 0 | N14: 0 | O14: 0
A15: =VALUE("1/"&C15&"/"&B15) -> 34700 | B15: =LEFT(D15,4) -> 1995 | C15: 1 | D15: 199501 | E15: =+IF([3]ARA!B2="","",[3]ARA!B2) -> 382261.7 | F15: =+IF([3]ARA!C2="","",[3]ARA!C2) | G15: =+IF([3]ARA!D2="","",[3]ARA!D2) | H15: =+IF([3]ARA!E2="","",[3]ARA!E2) -> 84.927296 | I15: =+IF([3]ARA!F2="","",[3]ARA!F2) -> 156322.55 | J15: =+IF([3]ARA!G2="","",[3]ARA!G2) | K15: =+IF([3]ARA!H2="","",[3]ARA!H2) -> 1688.532 | L15: =+IF([3]ARA!I2="","",[3]ARA!I2) -> 57.626117 | M15: =+IF([3]ARA!J2="","",[3]ARA!J2) -> 382261.7 | N15: =+'[1]Trim CM INICIAL_ECM'!J4 -> 67.016017 | O15: =+[2]anu!B2 -> 84.237632 | P15: 199501 | Q15: 2000
A16: =VALUE("1/"&C16&"/"&B16) -> 34731 | B16: =LEFT(D16,4) -> 1995 | C16: 2 | D16: 199502 | E16: =+IF([3]ARA!B3="","",[3]ARA!B3) -> 384978.52 | F16: =+IF([3]ARA!C3="","",[3]ARA!C3) | G16: =+IF([3]ARA!D3="","",[3]ARA!D3) | H16: =+IF([3]ARA!E3="","",[3]ARA!E3) -> 82.938838 | I16: =+IF([3]ARA!F3="","",[3]ARA!F3) -> 196358.66 | J16: =+IF([3]ARA!G3="","",[3]ARA!G3) | K16: =+IF([3]ARA!H3="","",[3]ARA!H3) -> 1712.3515 | L16: =+IF([3]ARA!I3="","",[3]ARA!I3) -> 57.683743 | M16: =+IF([3]ARA!J3="","",[3]ARA!J3) -> 384978.52 | N16: =+'[1]Trim CM INICIAL_ECM'!J5 -> 67.457788 | O16: =+[2]anu!B3 -> 87.471178 | P16: 199502 | Q16: =+Q15+1 -> 2001
A17: =VALUE("1/"&C17&"/"&B17) -> 34759 | B17: =LEFT(D17,4) -> 1995 | C17: 3 | D17: 199503 | E17: =+IF([3]ARA!B4="","",[3]ARA!B4) -> 388516.1 | F17: =+IF([3]ARA!C4="","",[3]ARA!C4) | G17: =+IF([3]ARA!D4="","",[3]ARA!D4) | H17: =+IF([3]ARA!E4="","",[3]ARA!E4) -> 93.833286 | I17: =+IF([3]ARA!F4="","",[3]ARA!F4) -> 222793.77 | J17: =+IF([3]ARA!G4="","",[3]ARA!G4) | K17: =+IF([3]ARA!H4="","",[3]ARA!H4) -> 1724.2612 | L17: =+IF([3]ARA!I4="","",[3]ARA!I4) -> 58.087529 | M17: =+IF([3]ARA!J4="","",[3]ARA!J4) -> 388516.1 | N17: =+'[1]Trim CM INICIAL_ECM'!J6 -> 67.756519 | O17: =+[2]anu!B4 -> 90.579301 | P17: 199503 | Q17: =+Q16+1 -> 2002
A18: =VALUE("1/"&C18&"/"&B18) -> 34790 | B18: =LEFT(D18,4) -> 1995 | C18: 4 | D18: 199504 | E18: =+IF([3]ARA!B5="","",[3]ARA!B5) -> 388207.45 | F18: =+IF([3]ARA!C5="","",[3]ARA!C5) | G18: =+IF([3]ARA!D5="","",[3]ARA!D5) | H18: =+IF([3]ARA!E5="","",[3]ARA!E5) -> 78.724459 | I18: =+IF([3]ARA!F5="","",[3]ARA!F5) -> 261490.66 | J18: =+IF([3]ARA!G5="","",[3]ARA!G5) | K18: =+IF([3]ARA!H5="","",[3]ARA!H5) -> 1324.6243 | L18: =+IF([3]ARA!I5="","",[3]ARA!I5) -> 58.377967 | M18: =+IF([3]ARA!J5="","",[3]ARA!J5) -> 388207.45 | N18: =+'[1]Trim CM INICIAL_ECM'!J7 -> 68.269558 | O18: =+[2]anu!B5 -> 94.186666 | P18: 199504 | Q18: =+Q17+1 -> 2003
A19: =VALUE("1/"&C19&"/"&B19) -> 34820 | B19: =LEFT(D19,4) -> 1995 | C19: 5 | D19: 199505 | E19: =+IF([3]ARA!B6="","",[3]ARA!B6) -> 389927.06 | F19: =+IF([3]ARA!C6="","",[3]ARA!C6) | G19: =+IF([3]ARA!D6="","",[3]ARA!D6) | H19: =+IF([3]ARA!E6="","",[3]ARA!E6) -> 92.004407 | I19: =+IF([3]ARA!F6="","",[3]ARA!F6) -> 199465.99 | J19: =+IF([3]ARA!G6="","",[3]ARA!G6) | K19: =+IF([3]ARA!H6="","",[3]ARA!H6) -> 1491.3602 | L19: =+IF([3]ARA!I6="","",[3]ARA!I6) -> 58.494723 | M19: =+IF([3]ARA!J6="","",[3]ARA!J6) -> 389927.06 | N19: =+'[1]Trim CM INICIAL_ECM'!J8 -> 68.661842 | O19: =+[2]anu!B6 -> 97.421534 | P19: 199601 | Q19: =+Q18+1 -> 2004
A20: =VALUE("1/"&C20&"/"&B20) -> 34851 | B20: =LEFT(D20,4) -> 1995 | C20: 6 | D20: 199506 | E20: =+IF([3]ARA!B7="","",[3]ARA!B7) -> 392449.54 | F20: =+IF([3]ARA!C7="","",[3]ARA!C7) | G20: =+IF([3]ARA!D7="","",[3]ARA!D7) | H20: =+IF([3]ARA!E7="","",[3]ARA!E7) -> 92.163572 | I20: =+IF([3]ARA!F7="","",[3]ARA!F7) -> 209601.56 | J20: =+IF([3]ARA!G7="","",[3]ARA!G7) | K20: =+IF([3]ARA!H7="","",[3]ARA!H7) -> 1213.467 | L20: =+IF([3]ARA!I7="","",[3]ARA!I7) -> 58.494723 | M20: =+IF([3]ARA!J7="","",[3]ARA!J7) -> 392449.54 | N20: =+'[1]Trim CM INICIAL_ECM'!J9 -> 69.136714 | O20: =+[2]anu!B7 -> 100.69843 | P20: 199602 | Q20: =+Q19+1 -> 2005
A21: =VALUE("1/"&C21&"/"&B21) -> 34881 | B21: =LEFT(D21,4) -> 1995 | C21: 7 | D21: 199507 | E21: =+IF([3]ARA!B8="","",[3]ARA!B8) -> 397906.67 | F21: =+IF([3]ARA!C8="","",[3]ARA!C8) | G21: =+IF([3]ARA!D8="","",[3]ARA!D8) | H21: =+IF([3]ARA!E8="","",[3]ARA!E8) -> 86.914904 | I21: =+IF([3]ARA!F8="","",[3]ARA!F8) -> 246961.7 | J21: =+IF([3]ARA!G8="","",[3]ARA!G8) | K21: =+IF([3]ARA!H8="","",[3]ARA!H8) -> 1353.7369 | L21: =+IF([3]ARA!I8="","",[3]ARA!I8) -> 58.553218 | M21: =+IF([3]ARA!J8="","",[3]ARA!J8) -> 397906.67 | N21: =+'[1]Trim CM INICIAL_ECM'!J10 -> 69.703856 | O21: =+[2]anu!B8 -> 104.7389 | P21: 199603 | Q21: =+Q20+1 -> 2006
A22: =VALUE("1/"&C22&"/"&B22) -> 34912 | B22: =LEFT(D22,4) -> 1995 | C22: 8 | D22: 199508 | E22: =+IF([3]ARA!B9="","",[3]ARA!B9) -> 399299.69 | F22: =+IF([3]ARA!C9="","",[3]ARA!C9) | G22: =+IF([3]ARA!D9="","",[3]ARA!D9) | H22: =+IF([3]ARA!E9="","",[3]ARA!E9) -> 48.984243 | I22: =+IF([3]ARA!F9="","",[3]ARA!F9) -> 349085.24 | J22: =+IF([3]ARA!G9="","",[3]ARA!G9) | K22: =+IF([3]ARA!H9="","",[3]ARA!H9) -> 1143.332 | L22: =+IF([3]ARA!I9="","",[3]ARA!I9) -> 58.845984 | M22: =+IF([3]ARA!J9="","",[3]ARA!J9) -> 399299.69 | N22: =+'[1]Trim CM INICIAL_ECM'!J11 -> 70.050606 | O22: =+[2]anu!B9 -> 108.3741 | P22: 199604 | Q22: =+Q21+1 -> 2007
A23: =VALUE("1/"&C23&"/"&B23) -> 34943 | B23: =LEFT(D23,4) -> 1995 | C23: 9 | D23: 199509 | E23: =+IF([3]ARA!B10="","",[3]ARA!B10) -> 395263.72 | F23: =+IF([3]ARA!C10="","",[3]ARA!C10) | G23: =+IF([3]ARA!D10="","",[3]ARA!D10) | H23: =+IF([3]ARA!E10="","",[3]ARA!E10) -> 86.279199 | I23: =+IF([3]ARA!F10="","",[3]ARA!F10) -> 252026.35 | J23: =+IF([3]ARA!G10="","",[3]ARA!G10) | K23: =+IF([3]ARA!H10="","",[3]ARA!H10) -> 1332.5641 | L23: =+IF([3]ARA!I10="","",[3]ARA!I10) -> 59.140214 | M23: =+IF([3]ARA!J10="","",[3]ARA!J10) -> 395263.72 | N23: =+'[1]Trim CM INICIAL_ECM'!J12 -> 70.749209 | O23: =+[2]anu!B10 -> 108.48215 | P23: 199701 | Q23: =+Q22+1 -> 2008
A24: =VALUE("1/"&C24&"/"&B24) -> 34973 | B24: =LEFT(D24,4) -> 1995 | C24: 10 | D24: 199510 | E24: =+IF([3]ARA!B11="","",[3]ARA!B11) -> 391590.02 | F24: =+IF([3]ARA!C11="","",[3]ARA!C11) | G24: =+IF([3]ARA!D11="","",[3]ARA!D11) | H24: =+IF([3]ARA!E11="","",[3]ARA!E11) -> 87.312537 | I24: =+IF([3]ARA!F11="","",[3]ARA!F11) -> 209035.56 | J24: =+IF([3]ARA!G11="","",[3]ARA!G11) | K24: =+IF([3]ARA!H11="","",[3]ARA!H11) -> 1353.7369 | L24: =+IF([3]ARA!I11="","",[3]ARA!I11) -> 59.258494 | M24: =+IF([3]ARA!J11="","",[3]ARA!J11) -> 391590.02 | N24: =+'[1]Trim CM INICIAL_ECM'!J13 -> 71.387254 | O24: =+[2]anu!B11 -> 104.02309 | P24: 199702 | Q24: =+Q23+1 -> 2009
A25: =VALUE("1/"&C25&"/"&B25) -> 35004 | B25: =LEFT(D25,4) -> 1995 | C25: 11 | D25: 199511 | E25: =+IF([3]ARA!B12="","",[3]ARA!B12) -> 391062.7 | F25: =+IF([3]ARA!C12="","",[3]ARA!C12) | G25: =+IF([3]ARA!D12="","",[3]ARA!D12) | H25: =+IF([3]ARA!E12="","",[3]ARA!E12) -> 89.618754 | I25: =+IF([3]ARA!F12="","",[3]ARA!F12) -> 143648.13 | J25: =+IF([3]ARA!G12="","",[3]ARA!G12) | K25: =+IF([3]ARA!H12="","",[3]ARA!H12) -> 838.97282 | L25: =+IF([3]ARA!I12="","",[3]ARA!I12) -> 59.495528 | M25: =+IF([3]ARA!J12="","",[3]ARA!J12) -> 391062.7 | N25: =+'[1]Trim CM INICIAL_ECM'!J14 -> 72.179702 | O25: =+[2]anu!B12 -> 102.64082 | P25: 199703 | Q25: =+Q24+1 -> 2010
A26: =VALUE("1/"&C26&"/"&B26) -> 35034 | B26: =LEFT(D26,4) -> 1995 | C26: 12 | D26: 199512 | E26: =+IF([3]ARA!B13="","",[3]ARA!B13) -> 392322.22 | F26: =+IF([3]ARA!C13="","",[3]ARA!C13) | G26: =+IF([3]ARA!D13="","",[3]ARA!D13) | H26: =+IF([3]ARA!E13="","",[3]ARA!E13) -> 75.464583 | I26: =+IF([3]ARA!F13="","",[3]ARA!F13) -> 139223.74 | J26: =+IF([3]ARA!G13="","",[3]ARA!G13) | K26: =+IF([3]ARA!H13="","",[3]ARA!H13) -> 1152.5951 | L26: =+IF([3]ARA!I13="","",[3]ARA!I13) -> 59.555024 | M26: =+IF([3]ARA!J13="","",[3]ARA!J13) -> 392322.22 | N26: =+'[1]Trim CM INICIAL_ECM'!J15 -> 73.193535 | O26: =+[2]anu!B13 -> 102.3609 | P26: 199704 | Q26: =+Q25+1 -> 2011
A27: =VALUE("1/"&C27&"/"&B27) -> 35065 | B27: =LEFT(D27,4) -> 1996 | C27: 1 | D27: 199601 | E27: =+IF([3]ARA!B14="","",[3]ARA!B14) -> 385920.97 | F27: =+IF([3]ARA!C14="","",[3]ARA!C14) | G27: =+IF([3]ARA!D14="","",[3]ARA!D14) | H27: =+IF([3]ARA!E14="","",[3]ARA!E14) -> 85.165856 | I27: =+IF([3]ARA!F14="","",[3]ARA!F14) -> 162577.25 | J27: =+IF([3]ARA!G14="","",[3]ARA!G14) | K27: =+IF([3]ARA!H14="","",[3]ARA!H14) -> 1533.7058 | L27: =+IF([3]ARA!I14="","",[3]ARA!I14) -> 59.793244 | M27: =+IF([3]ARA!J14="","",[3]ARA!J14) -> 385920.97 | N27: =+'[1]Trim CM INICIAL_ECM'!J16 -> 73.809914 | O27: =+[2]anu!B14 -> 98.790917 | P27: 199801 | Q27: =+Q26+1 -> 2012
... A45: =VALUE("1/"&C45&"/"&B45) -> 35612 | B45: =LEFT(D45,4) -> 1997 | C45: 7 | D45: 199707 | E45: =+IF([3]ARA!B32="","",[3]ARA!B32) -> 416343.17 | F45: =+IF([3]ARA!C32="","",[3]ARA!C32) | G45: =+IF([3]ARA!D32="","",[3]ARA!D32) | H45: =+IF([3]ARA!E32="","",[3]ARA!E32) -> 101.54651 | I45: =+IF([3]ARA!F32="","",[3]ARA!F32) -> 316037.42 | J45: =+IF([3]ARA!G32="","",[3]ARA!G32) -> 84203 | K45: =+IF([3]ARA!H32="","",[3]ARA!H32) -> 1374.9097 | L45: =+IF([3]ARA!I32="","",[3]ARA!I32) -> 61.979268 | M45: =+IF([3]ARA!J32="","",[3]ARA!J32) -> 416343.17 | N45: =+'[1]Trim CM INICIAL_ECM'!J34 -> 88.1866 | O45: =+[2]anu!B32 -> 133.35611 | P45: 200203 | Q45: =+Q44+1 -> 2030
A46: =VALUE("1/"&C46&"/"&B46) -> 35643 | B46: =LEFT(D46,4) -> 1997 | C46: 8 | D46: 199708 | E46: =+IF([3]ARA!B33="","",[3]ARA!B33) -> 418074.07 | F46: =+IF([3]ARA!C33="","",[3]ARA!C33) | G46: =+IF([3]ARA!D33="","",[3]ARA!D33) | H46: =+IF([3]ARA!E33="","",[3]ARA!E33) -> 54.550634 | I46: =+IF([3]ARA!F33="","",[3]ARA!F33) -> 457071.73 | J46: =+IF([3]ARA!G33="","",[3]ARA!G33) -> 58466 | K46: =+IF([3]ARA!H33="","",[3]ARA!H33) -> 1262.4291 | L46: =+IF([3]ARA!I33="","",[3]ARA!I33) -> 62.289165 | M46: =+IF([3]ARA!J33="","",[3]ARA!J33) -> 418074.07 | N46: =+'[1]Trim CM INICIAL_ECM'!J35 -> 88.87513 | P46: 200204
A47: =VALUE("1/"&C47&"/"&B47) -> 35674 | B47: =LEFT(D47,4) -> 1997 | C47: 9 | D47: 199709 | E47: =+IF([3]ARA!B34="","",[3]ARA!B34) -> 414444.83 | F47: =+IF([3]ARA!C34="","",[3]ARA!C34) | G47: =+IF([3]ARA!D34="","",[3]ARA!D34) | H47: =+IF([3]ARA!E34="","",[3]ARA!E34) -> 99.479518 | I47: =+IF([3]ARA!F34="","",[3]ARA!F34) -> 271311 | J47: =+IF([3]ARA!G34="","",[3]ARA!G34) -> 65210 | K47: =+IF([3]ARA!H34="","",[3]ARA!H34) -> 1426.5184 | L47: =+IF([3]ARA!I34="","",[3]ARA!I34) -> 62.60061 | M47: =+IF([3]ARA!J34="","",[3]ARA!J34) -> 414444.83 | N47: =+'[1]Trim CM INICIAL_ECM'!J36 -> 89.731812 | P47: 200301
A48: =VALUE("1/"&C48&"/"&B48) -> 35704 | B48: =LEFT(D48,4) -> 1997 | C48: 10 | D48: 199710 | E48: =+IF([3]ARA!B35="","",[3]ARA!B35) -> 412715.14 | F48: =+IF([3]ARA!C35="","",[3]ARA!C35) | G48: =+IF([3]ARA!D35="","",[3]ARA!D35) | H48: =+IF([3]ARA!E35="","",[3]ARA!E35) -> 106.87436 | I48: =+IF([3]ARA!F35="","",[3]ARA!F35) -> 214437.49 | J48: =+IF([3]ARA!G35="","",[3]ARA!G35) -> 72051 | K48: =+IF([3]ARA!H35="","",[3]ARA!H35) -> 1746.7573 | L48: =+IF([3]ARA!I35="","",[3]ARA!I35) -> 62.60061 | M48: =+IF([3]ARA!J35="","",[3]ARA!J35) -> 412715.14 | N48: =+'[1]Trim CM INICIAL_ECM'!J37 -> 90.07568 | P48: 200302
A49: =VALUE("1/"&C49&"/"&B49) -> 35735 | B49: =LEFT(D49,4) -> 1997 | C49: 11 | D49: 199711 | E49: =+IF([3]ARA!B36="","",[3]ARA!B36) -> 413719.93 | F49: =+IF([3]ARA!C36="","",[3]ARA!C36) | G49: =+IF([3]ARA!D36="","",[3]ARA!D36) | H49: =+IF([3]ARA!E36="","",[3]ARA!E36) -> 98.445446 | I49: =+IF([3]ARA!F36="","",[3]ARA!F36) -> 140367.74 | J49: =+IF([3]ARA!G36="","",[3]ARA!G36) -> 78174 | K49: =+IF([3]ARA!H36="","",[3]ARA!H36) -> 1762.6369 | L49: =+IF([3]ARA!I36="","",[3]ARA!I36) -> 62.60061 | M49: =+IF([3]ARA!J36="","",[3]ARA!J36) -> 413719.93 | N49: =+'[1]Trim CM INICIAL_ECM'!J38 -> 90.746529 | P49: 200303
A50: =VALUE("1/"&C50&"/"&B50) -> 35765 | B50: =LEFT(D50,4) -> 1997 | C50: 12 | D50: 199712 | E50: =+IF([3]ARA!B37="","",[3]ARA!B37) -> 413451.63 | F50: =+IF([3]ARA!C37="","",[3]ARA!C37) | G50: =+IF([3]ARA!D37="","",[3]ARA!D37) | H50: =+IF([3]ARA!E37="","",[3]ARA!E37) -> 87.55164 | I50: =+IF([3]ARA!F37="","",[3]ARA!F37) -> 181977.09 | J50: =+IF([3]ARA!G37="","",[3]ARA!G37) -> 84467 | K50: =+IF([3]ARA!H37="","",[3]ARA!H37) -> 1642.2165 | L50: =+IF([3]ARA!I37="","",[3]ARA!I37) -> 62.788412 | M50: =+IF([3]ARA!J37="","",[3]ARA!J37) -> 413451.63 | N50: =+'[1]Trim CM INICIAL_ECM'!J39 -> 91.507449 | P50: 200304
A51: =VALUE("1/"&C51&"/"&B51) -> 35796 | B51: =LEFT(D51,4) -> 1998 | C51: 1 | D51: 199801 | E51: =+IF([3]ARA!B38="","",[3]ARA!B38) -> 409457.79 | F51: =+IF([3]ARA!C38="","",[3]ARA!C38) | G51: =+IF([3]ARA!D38="","",[3]ARA!D38) | H51: =+IF([3]ARA!E38="","",[3]ARA!E38) -> 92.87929 | I51: =+IF([3]ARA!F38="","",[3]ARA!F38) -> 217915.51 | J51: =+IF([3]ARA!G38="","",[3]ARA!G38) -> 97362 | K51: =+IF([3]ARA!H38="","",[3]ARA!H38) -> 1499.3 | L51: =+IF([3]ARA!I38="","",[3]ARA!I38) -> 62.913989 | M51: =+IF([3]ARA!J38="","",[3]ARA!J38) -> 409457.79 | N51: =+'[1]Trim CM INICIAL_ECM'!J40 -> 92.042783 | P51: 200401
A52: =VALUE("1/"&C52&"/"&B52) -> 35827 | B52: =LEFT(D52,4) -> 1998 | C52: 2 | D52: 199802 | E52: =+IF([3]ARA!B39="","",[3]ARA!B39) -> 413391.26 | F52: =+IF([3]ARA!C39="","",[3]ARA!C39) | G52: =+IF([3]ARA!D39="","",[3]ARA!D39) | H52: =+IF([3]ARA!E39="","",[3]ARA!E39) -> 96.616192 | I52: =+IF([3]ARA!F39="","",[3]ARA!F39) -> 244997.24 | J52: =+IF([3]ARA!G39="","",[3]ARA!G39) -> 97501 | K52: =+IF([3]ARA!H39="","",[3]ARA!H39) -> 1586.6379 | L52: =+IF([3]ARA!I39="","",[3]ARA!I39) -> 62.536505 | M52: =+IF([3]ARA!J39="","",[3]ARA!J39) -> 413391.26 | N52: =+'[1]Trim CM INICIAL_ECM'!J41 -> 93.020239 | P52: 200402
A53: =VALUE("1/"&C53&"/"&B53) -> 35855 | B53: =LEFT(D53,4) -> 1998 | C53: 3 | D53: 199803 | E53: =+IF([3]ARA!B40="","",[3]ARA!B40) -> 417684.36 | F53: =+IF([3]ARA!C40="","",[3]ARA!C40) | G53: =+IF([3]ARA!D40="","",[3]ARA!D40) | H53: =+IF([3]ARA!E40="","",[3]ARA!E40) -> 103.1371 | I53: =+IF([3]ARA!F40="","",[3]ARA!F40) -> 252225.65 | J53: =+IF([3]ARA!G40="","",[3]ARA!G40) -> 100780 | K53: =+IF([3]ARA!H40="","",[3]ARA!H40) -> 1840.7117 | L53: =+IF([3]ARA!I40="","",[3]ARA!I40) -> 62.411432 | M53: =+IF([3]ARA!J40="","",[3]ARA!J40) -> 417684.36 | N53: =+'[1]Trim CM INICIAL_ECM'!J42 -> 93.804639 | P53: 200403
A54: =VALUE("1/"&C54&"/"&B54) -> 35886 | B54: =LEFT(D54,4) -> 1998 | C54: 4 | D54: 199804 | E54: =+IF([3]ARA!B41="","",[3]ARA!B41) -> 418339.7 | F54: =+IF([3]ARA!C41="","",[3]ARA!C41) | G54: =+IF([3]ARA!D41="","",[3]ARA!D41) | H54: =+IF([3]ARA!E41="","",[3]ARA!E41) -> 96.139263 | I54: =+IF([3]ARA!F41="","",[3]ARA!F41) -> 253452.27 | J54: =+IF([3]ARA!G41="","",[3]ARA!G41) -> 89664 | K54: =+IF([3]ARA!H41="","",[3]ARA!H41) -> 1759.9903 | L54: =+IF([3]ARA!I41="","",[3]ARA!I41) -> 62.536255 | M54: =+IF([3]ARA!J41="","",[3]ARA!J41) -> 418339.7 | N54: =+'[1]Trim CM INICIAL_ECM'!J43 -> 94.47041 | P54: 200404
A55: =VALUE("1/"&C55&"/"&B55) -> 35916 | B55: =LEFT(D55,4) -> 1998 | C55: 5 | D55: 199805 | E55: =+IF([3]ARA!B42="","",[3]ARA!B42) -> 421773.05 | F55: =+IF([3]ARA!C42="","",[3]ARA!C42) | G55: =+IF([3]ARA!D42="","",[3]ARA!D42) | H55: =+IF([3]ARA!E42="","",[3]ARA!E42) -> 100.91062 | I55: =+IF([3]ARA!F42="","",[3]ARA!F42) -> 234351.94 | J55: =+IF([3]ARA!G42="","",[3]ARA!G42) -> 80149 | K55: =+IF([3]ARA!H42="","",[3]ARA!H42) -> 1713.6748 | L55: =+IF([3]ARA!I42="","",[3]ARA!I42) -> 62.598791 | M55: =+IF([3]ARA!J42="","",[3]ARA!J42) -> 421773.05 | N55: =+'[1]Trim CM INICIAL_ECM'!J44 -> 95.314485 | P55: 200501
A56: =VALUE("1/"&C56&"/"&B56) -> 35947 | B56: =LEFT(D56,4) -> 1998 | C56: 6 | D56: 199806 | E56: =+IF([3]ARA!B43="","",[3]ARA!B43) -> 426100.2 | F56: =+IF([3]ARA!C43="","",[3]ARA!C43) | G56: =+IF([3]ARA!D43="","",[3]ARA!D43) | H56: =+IF([3]ARA!E43="","",[3]ARA!E43) -> 106.71572 | I56: =+IF([3]ARA!F43="","",[3]ARA!F43) -> 225084.36 | J56: =+IF([3]ARA!G43="","",[3]ARA!G43) -> 84398 | K56: =+IF([3]ARA!H43="","",[3]ARA!H43) -> 2084.199 | L56: =+IF([3]ARA!I43="","",[3]ARA!I43) -> 62.66139 | M56: =+IF([3]ARA!J43="","",[3]ARA!J43) -> 426100.2 | N56: =+'[1]Trim CM INICIAL_ECM'!J45 -> 96.160515 | P56: 200502
A57: =VALUE("1/"&C57&"/"&B57) -> 35977 | B57: =LEFT(D57,4) -> 1998 | C57: 7 | D57: 199807 | E57: =+IF([3]ARA!B44="","",[3]ARA!B44) -> 432037.05 | F57: =+IF([3]ARA!C44="","",[3]ARA!C44) | G57: =+IF([3]ARA!D44="","",[3]ARA!D44) | H57: =+IF([3]ARA!E44="","",[3]ARA!E44) -> 107.90807 | I57: =+IF([3]ARA!F44="","",[3]ARA!F44) -> 351161.07 | J57: =+IF([3]ARA!G44="","",[3]ARA!G44) -> 91898 | K57: =+IF([3]ARA!H44="","",[3]ARA!H44) -> 1147.3019 | L57: =+IF([3]ARA!I44="","",[3]ARA!I44) -> 63.037358 | M57: =+IF([3]ARA!J44="","",[3]ARA!J44) -> 432037.05 | N57: =+'[1]Trim CM INICIAL_ECM'!J46 -> 97.081208 | P57: 200503
...

Sheet AST
D1: Acrónimo | E1: AFI | F1: IAS | G1: ICM | H1: IPI | I1: PER | J1: GAS | K1: HIP | L1: IPC | M1: AFIE | N1: PIB | O1: PIB_CCAA
D2: SA | E2: 0 | F2: 0 | G2: 0 | H2: 0 | I2: 0 | J2: 0 | K2: 0 | L2: 0 | M2: 0 | N2: 0 | O2: 0
D3: DEF | E3: 1 | F3: 1 | G3: 1 | H3: 1 | I3: 1 | J3: 1 | K3: 1 | L3: 1 | M3: 1 | N3: 1 | O3: 1
D4: Serie | E4: afiliados | F4: creditos | G4: depositos | H4: consumo productos petro | I4: hipotecas | J4: indice actividad serviciios | K4: indice comercio al por menor | L4: indice comercio al por menor | M4: indice comercio al por menor | N4: PIB ESPAÑA | O4: PIB ccaa
D5: Enlaces y Deflactores
D6: Fecha INI MOD | E6: 34700 | F6: 34700 | G6: 34700 | H6: 34731 | I6: 34759 | J6: 34790 | K6: 34820 | L6: 34851 | M6: 34881 | N6: 34973 | O6: 35004
D7: Cod | E7: SC | F7: 190000m | G7: 229000cc.d | H7: 229000cc.d | I7: 229000cc.d | J7: 229000cc.d | K7: 229000cc.d | L7: 229000cc.d | M7: 229000cc.d | N7: 229000cc.d | O7: 229000cc.d
D8: Año | E8: 1995 | F8: 2005 | G8: 2001 | H8: 1995 | I8: 1995 | J8: 1997 | K8: 1995 | L8: 1995 | M8: 1995 | N8: 1995 | O8: 2000
D9: Freq | E9: 12 | F9: 12 | G9: 12 | H9: 12 | I9: 12 | J9: 12 | K9: 12 | L9: 12 | M9: 12 | N9: 4 | O9: 1
D10: Mes INI | E10: 8 | F10: 1 | G10: 1 | H10: 1 | I10: 1 | J10: 1 | K10: 1 | L10: 1 | M10: 1 | N10: 1 | O10: 0
D11: type | E11: 6 | F11: 6 | G11: 6 | H11: 6 | I11: 6 | J11: 6 | K11: 6 | L11: 6 | M11: 6 | N11: 2 | O11: 1
D12: dlg | E12: 1 | F12: 1 | G12: 1 | H12: 1 | I12: 1 | J12: 1 | K12: 1 | L12: 1 | M12: 1 | N12: 1 | O12: 1
D13: selector | E13: =+AND!E13 -> 1 | F13: =+AND!F13 -> 1 | G13: =+AND!G13 -> 1 | H13: =+AND!H13 -> 1 | I13: =+AND!I13 -> 1 | J13: =+AND!J13 -> 1 | K13: =+AND!K13 -> 1 | L13: =+AND!L13 -> 1 | ... O13: =+AND!O13 -> 1
A14: Posición de outlier---> | D14: outliers | E14: 0 | F14: 0 | G14: 0 | H14: 0 | I14: 0 | J14: 0 | K14: 0 | L14: 0 | M14: 0 | N14: 0 | O14: 0
A15: =VALUE("1/"&C15&"/"&B15) -> 34700 | B15: =LEFT(D15,4) -> 1995 | C15: 1 | D15: 199501 | E15: =+IF([3]AST!B2="","",[3]AST!B2) -> 299181.93 | F15: =+IF([3]AST!C2="","",[3]AST!C2) | G15: =+IF([3]AST!D2="","",[3]AST!D2) | H15: =+IF([3]AST!E2="","",[3]AST!E2) -> 101.25675 | I15: =+IF([3]AST!F2="","",[3]AST!F2) -> 38752.342 | J15: =+IF([3]AST!G2="","",[3]AST!G2) | K15: =+IF([3]AST!H2="","",[3]AST!H2) -> 1303.0942 | L15: =+IF([3]AST!I2="","",[3]AST!I2) -> 58.614219 | M15: =+IF([3]AST!J2="","",[3]AST!J2) -> 299181.93 | N15: =+'[1]Trim CM INICIAL_ECM'!J4 -> 67.016017 | O15: =+[2]anu!B2 -> 84.237632 | P15: 199501 | Q15: 2000
A16: =VALUE("1/"&C16&"/"&B16) -> 34731 | B16: =LEFT(D16,4) -> 1995 | C16: 2 | D16: 199502 | E16: =+IF([3]AST!B3="","",[3]AST!B3) -> 300302.78 | F16: =+IF([3]AST!C3="","",[3]AST!C3) | G16: =+IF([3]AST!D3="","",[3]AST!D3) | H16: =+IF([3]AST!E3="","",[3]AST!E3) -> 98.175941 | I16: =+IF([3]AST!F3="","",[3]AST!F3) -> 50328.496 | J16: =+IF([3]AST!G3="","",[3]AST!G3) | K16: =+IF([3]AST!H3="","",[3]AST!H3) -> 1101.3957 | L16: =+IF([3]AST!I3="","",[3]AST!I3) -> 59.024519 | M16: =+IF([3]AST!J3="","",[3]AST!J3) -> 300302.78 | N16: =+'[1]Trim CM INICIAL_ECM'!J5 -> 67.457788 | O16: =+[2]anu!B3 -> 87.471178 | P16: 199502 | Q16: =+Q15+1 -> 2001
A17: =VALUE("1/"&C17&"/"&B17) -> 34759 | B17: =LEFT(D17,4) -> 1995 | C17: 3 | D17: 199503 | E17: =+IF([3]AST!B4="","",[3]AST!B4) -> 303423.66 | F17: =+IF([3]AST!C4="","",[3]AST!C4) | G17: =+IF([3]AST!D4="","",[3]AST!D4) | H17: =+IF([3]AST!E4="","",[3]AST!E4) -> 111.52614 | I17: =+IF([3]AST!F4="","",[3]AST!F4) -> 54938.747 | J17: =+IF([3]AST!G4="","",[3]AST!G4) | K17: =+IF([3]AST!H4="","",[3]AST!H4) -> 944.92663 | L17: =+IF([3]AST!I4="","",[3]AST!I4) -> 59.319642 | M17: =+IF([3]AST!J4="","",[3]AST!J4) -> 303423.66 | N17: =+'[1]Trim CM INICIAL_ECM'!J6 -> 67.756519 | O17: =+[2]anu!B4 -> 90.579301 | P17: 199503 | Q17: =+Q16+1 -> 2002
A18: =VALUE("1/"&C18&"/"&B18) -> 34790 | B18: =LEFT(D18,4) -> 1995 | C18: 4 | D18: 199504 | E18: =+IF([3]AST!B5="","",[3]AST!B5) -> 302311.81 | F18: =+IF([3]AST!C5="","",[3]AST!C5) | G18: =+IF([3]AST!D5="","",[3]AST!D5) | H18: =+IF([3]AST!E5="","",[3]AST!E5) -> 101.25636 | I18: =+IF([3]AST!F5="","",[3]AST!F5) -> 96805.45 | J18: =+IF([3]AST!G5="","",[3]AST!G5) | K18: =+IF([3]AST!H5="","",[3]AST!H5) -> 869.13692 | L18: =+IF([3]AST!I5="","",[3]AST!I5) -> 59.734879 | M18: =+IF([3]AST!J5="","",[3]AST!J5) -> 302311.81 | N18: =+'[1]Trim CM INICIAL_ECM'!J7 -> 68.269558 | O18: =+[2]anu!B5 -> 94.186666 | P18: 199504 | Q18: =+Q17+1 -> 2003
A19: =VALUE("1/"&C19&"/"&B19) -> 34820 | B19: =LEFT(D19,4) -> 1995 | C19: 5 | D19: 199505 | E19: =+IF([3]AST!B6="","",[3]AST!B6) -> 302643.03 | F19: =+IF([3]AST!C6="","",[3]AST!C6) | G19: =+IF([3]AST!D6="","",[3]AST!D6) | H19: =+IF([3]AST!E6="","",[3]AST!E6) -> 114.29881 | I19: =+IF([3]AST!F6="","",[3]AST!F6) -> 83503.814 | J19: =+IF([3]AST!G6="","",[3]AST!G6) | K19: =+IF([3]AST!H6="","",[3]AST!H6) -> 1338.5442 | L19: =+IF([3]AST!I6="","",[3]AST!I6) -> 59.734879 | M19: =+IF([3]AST!J6="","",[3]AST!J6) -> 302643.03 | N19: =+'[1]Trim CM INICIAL_ECM'!J8 -> 68.661842 | O19: =+[2]anu!B6 -> 97.421534 | P19: 199601 | Q19: =+Q18+1 -> 2004
A20: =VALUE("1/"&C20&"/"&B20) -> 34851 | B20: =LEFT(D20,4) -> 1995 | C20: 6 | D20: 199506 | E20: =+IF([3]AST!B7="","",[3]AST!B7) -> 305323.44 | F20: =+IF([3]AST!C7="","",[3]AST!C7) | G20: =+IF([3]AST!D7="","",[3]AST!D7) | H20: =+IF([3]AST!E7="","",[3]AST!E7) -> 112.55302 | I20: =+IF([3]AST!F7="","",[3]AST!F7) -> 90522.719 | J20: =+IF([3]AST!G7="","",[3]AST!G7) | K20: =+IF([3]AST!H7="","",[3]AST!H7) -> 1041.4974 | L20: =+IF([3]AST!I7="","",[3]AST!I7) -> 59.675144 | M20: =+IF([3]AST!J7="","",[3]AST!J7) -> 305323.44 | N20: =+'[1]Trim CM INICIAL_ECM'!J9 -> 69.136714 | O20: =+[2]anu!B7 -> 100.69843 | P20: 199602 | Q20: =+Q19+1 -> 2005
A21: =VALUE("1/"&C21&"/"&B21) -> 34881 | B21: =LEFT(D21,4) -> 1995 | C21: 7 | D21: 199507 | E21: =+IF([3]AST!B8="","",[3]AST!B8) -> 306917.91 | F21: =+IF([3]AST!C8="","",[3]AST!C8) | G21: =+IF([3]AST!D8="","",[3]AST!D8) | H21: =+IF([3]AST!E8="","",[3]AST!E8) -> 99.715853 | I21: =+IF([3]AST!F8="","",[3]AST!F8) -> 150625.43 | J21: =+IF([3]AST!G8="","",[3]AST!G8) | K21: =+IF([3]AST!H8="","",[3]AST!H8) -> 988.93356 | L21: =+IF([3]AST!I8="","",[3]AST!I8) -> 59.675144 | M21: =+IF([3]AST!J8="","",[3]AST!J8) -> 306917.91 | N21: =+'[1]Trim CM INICIAL_ECM'!J10 -> 69.703856 | O21: =+[2]anu!B8 -> 104.7389 | P21: 199603 | Q21: =+Q20+1 -> 2006
A22: =VALUE("1/"&C22&"/"&B22) -> 34912 | B22: =LEFT(D22,4) -> 1995 | C22: 8 | D22: 199508 | E22: =+IF([3]AST!B9="","",[3]AST!B9) -> 309544.17 | F22: =+IF([3]AST!C9="","",[3]AST!C9) | G22: =+IF([3]AST!D9="","",[3]AST!D9) | H22: =+IF([3]AST!E9="","",[3]AST!E9) -> 85.646711 | I22: =+IF([3]AST!F9="","",[3]AST!F9) -> 216447.05 | J22: =+IF([3]AST!G9="","",[3]AST!G9) | K22: =+IF([3]AST!H9="","",[3]AST!H9) -> 893.58521 | L22: =+IF([3]AST!I9="","",[3]AST!I9) -> 59.913845 | M22: =+IF([3]AST!J9="","",[3]AST!J9) -> 309544.17 | N22: =+'[1]Trim CM INICIAL_ECM'!J11 -> 70.050606 | O22: =+[2]anu!B9 -> 108.3741 | P22: 199604 | Q22: =+Q21+1 -> 2007
A23: =VALUE("1/"&C23&"/"&B23) -> 34943 | B23: =LEFT(D23,4) -> 1995 | C23: 9 | D23: 199509 | E23: =+IF([3]AST!B10="","",[3]AST!B10) -> 306036.16 | F23: =+IF([3]AST!C10="","",[3]AST!C10) | G23: =+IF([3]AST!D10="","",[3]AST!D10) | H23: =+IF([3]AST!E10="","",[3]AST!E10) -> 101.87296 | I23: =+IF([3]AST!F10="","",[3]AST!F10) -> 129753.41 | J23: =+IF([3]AST!G10="","",[3]AST!G10) | K23: =+IF([3]AST!H10="","",[3]AST!H10) -> 1194.2992 | L23: =+IF([3]AST!I10="","",[3]AST!I10) -> 60.1535 | M23: =+IF([3]AST!J10="","",[3]AST!J10) -> 306036.16 | N23: =+'[1]Trim CM INICIAL_ECM'!J12 -> 70.749209 | O23: =+[2]anu!B10 -> 108.48215 | P23: 199701 | Q23: =+Q22+1 -> 2008
A24: =VALUE("1/"&C24&"/"&B24) -> 34973 | B24: =LEFT(D24,4) -> 1995 | C24: 10 | D24: 199510 | E24: =+IF([3]AST!B11="","",[3]AST!B11) -> 301624.05 | F24: =+IF([3]AST!C11="","",[3]AST!C11) | G24: =+IF([3]AST!D11="","",[3]AST!D11) | H24: =+IF([3]AST!E11="","",[3]AST!E11) -> 104.33771 | I24: =+IF([3]AST!F11="","",[3]AST!F11) -> 88487.342 | J24: =+IF([3]AST!G11="","",[3]AST!G11) | K24: =+IF([3]AST!H11="","",[3]AST!H11) -> 834.9093 | L24: =+IF([3]AST!I11="","",[3]AST!I11) -> 60.394114 | M24: =+IF([3]AST!J11="","",[3]AST!J11) -> 301624.05 | N24: =+'[1]Trim CM INICIAL_ECM'!J13 -> 71.387254 | O24: =+[2]anu!B11 -> 104.02309 | P24: 199702 | Q24: =+Q23+1 -> 2009
A25: =VALUE("1/"&C25&"/"&B25) -> 35004 | B25: =LEFT(D25,4) -> 1995 | C25: 11 | D25: 199511 | E25: =+IF([3]AST!B12="","",[3]AST!B12) -> 301156.47 | F25: =+IF([3]AST!C12="","",[3]AST!C12) | G25: =+IF([3]AST!D12="","",[3]AST!D12) | H25: =+IF([3]AST!E12="","",[3]AST!E12) -> 103.92653 | I25: =+IF([3]AST!F12="","",[3]AST!F12) -> 53607.981 | J25: =+IF([3]AST!G12="","",[3]AST!G12) | K25: =+IF([3]AST!H12="","",[3]AST!H12) -> 891.14038 | L25: =+IF([3]AST!I12="","",[3]AST!I12) -> 60.575296 | M25: =+IF([3]AST!J12="","",[3]AST!J12) -> 301156.47 | N25: =+'[1]Trim CM INICIAL_ECM'!J14 -> 72.179702 | O25: =+[2]anu!B12 -> 102.64082 | P25: 199703 | Q25: =+Q24+1 -> 2010
A26: =VALUE("1/"&C26&"/"&B26) -> 35034 | B26: =LEFT(D26,4) -> 1995 | C26: 12 | D26: 199512 | E26: =+IF([3]AST!B13="","",[3]AST!B13) -> 300704.01 | F26: =+IF([3]AST!C13="","",[3]AST!C13) | G26: =+IF([3]AST!D13="","",[3]AST!D13) | H26: =+IF([3]AST!E13="","",[3]AST!E13) -> 91.398325 | I26: =+IF([3]AST!F13="","",[3]AST!F13) -> 52834.024 | J26: =+IF([3]AST!G13="","",[3]AST!G13) | K26: =+IF([3]AST!H13="","",[3]AST!H13) -> 1019.4939 | L26: =+IF([3]AST!I13="","",[3]AST!I13) -> 60.696447 | M26: =+IF([3]AST!J13="","",[3]AST!J13) -> 300704.01 | N26: =+'[1]Trim CM INICIAL_ECM'!J15 -> 73.193535 | O26: =+[2]anu!B13 -> 102.3609 | P26: 199704 | Q26: =+Q25+1 -> 2011
A27: =VALUE("1/"&C27&"/"&B27) -> 35065 | B27: =LEFT(D27,4) -> 1996 | C27: 1 | D27: 199601 | E27: =+IF([3]AST!B14="","",[3]AST!B14) -> 296978.91 | F27: =+IF([3]AST!C14="","",[3]AST!C14) | G27: =+IF([3]AST!D14="","",[3]AST!D14) | H27: =+IF([3]AST!E14="","",[3]AST!E14) -> 100.43519 | I27: =+IF([3]AST!F14="","",[3]AST!F14) -> 36073.476 | J27: =+IF([3]AST!G14="","",[3]AST!G14) | K27: =+IF([3]AST!H14="","",[3]AST!H14) -> 1164.9613 | L27: =+IF([3]AST!I14="","",[3]AST!I14) -> 61.060626 | M27: =+IF([3]AST!J14="","",[3]AST!J14) -> 296978.91 | N27: =+'[1]Trim CM INICIAL_ECM'!J16 -> 73.809914 | O27: =+[2]anu!B14 -> 98.790917 | P27: 199801 | Q27: =+Q26+1 -> 2012
... A45: =VALUE("1/"&C45&"/"&B45) -> 35612 | B45: =LEFT(D45,4) -> 1997 | C45: 7 | D45: 199707 | E45: =+IF([3]AST!B32="","",[3]AST!B32) -> 312247.39 | F45: =+IF([3]AST!C32="","",[3]AST!C32) | G45: =+IF([3]AST!D32="","",[3]AST!D32) | H45: =+IF([3]AST!E32="","",[3]AST!E32) -> 105.7748 | I45: =+IF([3]AST!F32="","",[3]AST!F32) -> 135823.97 | J45: =+IF([3]AST!G32="","",[3]AST!G32) -> 47452 | K45: =+IF([3]AST!H32="","",[3]AST!H32) -> 957.15078 | L45: =+IF([3]AST!I32="","",[3]AST!I32) -> 62.979284 | M45: =+IF([3]AST!J32="","",[3]AST!J32) -> 312247.39 | N45: =+'[1]Trim CM INICIAL_ECM'!J34 -> 88.1866 | O45: =+[2]anu!B32 -> 133.35611 | P45: 200203 | Q45: =+Q44+1 -> 2030
A46: =VALUE("1/"&C46&"/"&B46) -> 35643 | B46: =LEFT(D46,4) -> 1997 | C46: 8 | D46: 199708 | E46: =+IF([3]AST!B33="","",[3]AST!B33) -> 316229.56 | F46: =+IF([3]AST!C33="","",[3]AST!C33) | G46: =+IF([3]AST!D33="","",[3]AST!D33) | H46: =+IF([3]AST!E33="","",[3]AST!E33) -> 85.749405 | I46: =+IF([3]AST!F33="","",[3]AST!F33) -> 198129.39 | J46: =+IF([3]AST!G33="","",[3]AST!G33) -> 43408 | K46: =+IF([3]AST!H33="","",[3]AST!H33) -> 969.37493 | L46: =+IF([3]AST!I33="","",[3]AST!I33) -> 63.294181 | M46: =+IF([3]AST!J33="","",[3]AST!J33) -> 316229.56 | N46: =+'[1]Trim CM INICIAL_ECM'!J35 -> 88.87513 | P46: 200204
A47: =VALUE("1/"&C47&"/"&B47) -> 35674 | B47: =LEFT(D47,4) -> 1997 | C47: 9 | D47: 199709 | E47: =+IF([3]AST!B34="","",[3]AST!B34) -> 311735.82 | F47: =+IF([3]AST!C34="","",[3]AST!C34) | G47: =+IF([3]AST!D34="","",[3]AST!D34) | H47: =+IF([3]AST!E34="","",[3]AST!E34) -> 107.31577 | I47: =+IF([3]AST!F34="","",[3]AST!F34) -> 121754.49 | J47: =+IF([3]AST!G34="","",[3]AST!G34) -> 43041 | K47: =+IF([3]AST!H34="","",[3]AST!H34) -> 1095.2837 | L47: =+IF([3]AST!I34="","",[3]AST!I34) -> 63.484063 | M47: =+IF([3]AST!J34="","",[3]AST!J34) -> 311735.82 | N47: =+'[1]Trim CM INICIAL_ECM'!J36 -> 89.731812 | P47: 200301
A48: =VALUE("1/"&C48&"/"&B48) -> 35704 | B48: =LEFT(D48,4) -> 1997 | C48: 10 | D48: 199710 | E48: =+IF([3]AST!B35="","",[3]AST!B35) -> 309355.19 | F48: =+IF([3]AST!C35="","",[3]AST!C35) | G48: =+IF([3]AST!D35="","",[3]AST!D35) | H48: =+IF([3]AST!E35="","",[3]AST!E35) -> 114.40178 | I48: =+IF([3]AST!F35="","",[3]AST!F35) -> 86442.727 | J48: =+IF([3]AST!G35="","",[3]AST!G35) -> 44682 | K48: =+IF([3]AST!H35="","",[3]AST!H35) -> 1226.082 | L48: =+IF([3]AST!I35="","",[3]AST!I35) -> 63.484063 | M48: =+IF([3]AST!J35="","",[3]AST!J35) -> 309355.19 | N48: =+'[1]Trim CM INICIAL_ECM'!J37 -> 90.07568 | P48: 200302
A49: =VALUE("1/"&C49&"/"&B49) -> 35735 | B49: =LEFT(D49,4) -> 1997 | C49: 11 | D49: 199711 | E49: =+IF([3]AST!B36="","",[3]AST!B36) -> 310328.1 | F49: =+IF([3]AST!C36="","",[3]AST!C36) | G49: =+IF([3]AST!D36="","",[3]AST!D36) | H49: =+IF([3]AST!E36="","",[3]AST!E36) -> 103.72114 | I49: =+IF([3]AST!F36="","",[3]AST!F36) -> 53649.816 | J49: =+IF([3]AST!G36="","",[3]AST!G36) -> 46215 | K49: =+IF([3]AST!H36="","",[3]AST!H36) -> 951.03871 | L49: =+IF([3]AST!I36="","",[3]AST!I36) -> 63.738 | M49: =+IF([3]AST!J36="","",[3]AST!J36) -> 310328.1 | N49: =+'[1]Trim CM INICIAL_ECM'!J38 -> 90.746529 | P49: 200303
A50: =VALUE("1/"&C50&"/"&B50) -> 35765 | B50: =LEFT(D50,4) -> 1997 | C50: 12 | D50: 199712 | E50: =+IF([3]AST!B37="","",[3]AST!B37) -> 308700.89 | F50: =+IF([3]AST!C37="","",[3]AST!C37) | G50: =+IF([3]AST!D37="","",[3]AST!D37) | H50: =+IF([3]AST!E37="","",[3]AST!E37) -> 93.760304 | I50: =+IF([3]AST!F37="","",[3]AST!F37) -> 52278.235 | J50: =+IF([3]AST!G37="","",[3]AST!G37) -> 54851 | K50: =+IF([3]AST!H37="","",[3]AST!H37) -> 1477.8995 | L50: =+IF([3]AST!I37="","",[3]AST!I37) -> 63.929214 | M50: =+IF([3]AST!J37="","",[3]AST!J37) -> 308700.89 | N50: =+'[1]Trim CM INICIAL_ECM'!J39 -> 91.507449 | P50: 200304
A51: =VALUE("1/"&C51&"/"&B51) -> 35796 | B51: =LEFT(D51,4) -> 1998 | C51: 1 | D51: 199801 | E51: =+IF([3]AST!B38="","",[3]AST!B38) -> 306135.54 | F51: =+IF([3]AST!C38="","",[3]AST!C38) | G51: =+IF([3]AST!D38="","",[3]AST!D38) | H51: =+IF([3]AST!E38="","",[3]AST!E38) -> 96.840885 | I51: =+IF([3]AST!F38="","",[3]AST!F38) -> 39763.938 | J51: =+IF([3]AST!G38="","",[3]AST!G38) -> 51307 | K51: =+IF([3]AST!H38="","",[3]AST!H38) -> 1799.3946 | L51: =+IF([3]AST!I38="","",[3]AST!I38) -> 64.057072 | M51: =+IF([3]AST!J38="","",[3]AST!J38) -> 306135.54 | N51: =+'[1]Trim CM INICIAL_ECM'!J40 -> 92.042783 | P51: 200401
A52: =VALUE("1/"&C52&"/"&B52) -> 35827 | B52: =LEFT(D52,4) -> 1998 | C52: 2 | D52: 199802 | E52: =+IF([3]AST!B39="","",[3]AST!B39) -> 307784.86 | F52: =+IF([3]AST!C39="","",[3]AST!C39) | G52: =+IF([3]AST!D39="","",[3]AST!D39) | H52: =+IF([3]AST!E39="","",[3]AST!E39) -> 102.6945 | I52: =+IF([3]AST!F39="","",[3]AST!F39) -> 62741.837 | J52: =+IF([3]AST!G39="","",[3]AST!G39) -> 55621 | K52: =+IF([3]AST!H39="","",[3]AST!H39) -> 1309.2062 | L52: =+IF([3]AST!I39="","",[3]AST!I39) -> 63.928958 | M52: =+IF([3]AST!J39="","",[3]AST!J39) -> 307784.86 | N52: =+'[1]Trim CM INICIAL_ECM'!J41 -> 93.020239 | P52: 200402
A53: =VALUE("1/"&C53&"/"&B53) -> 35855 | B53: =LEFT(D53,4) -> 1998 | C53: 3 | D53: 199803 | E53: =+IF([3]AST!B40="","",[3]AST!B40) -> 310456.21 | F53: =+IF([3]AST!C40="","",[3]AST!C40) | G53: =+IF([3]AST!D40="","",[3]AST!D40) | H53: =+IF([3]AST!E40="","",[3]AST!E40) -> 115.12044 | I53: =+IF([3]AST!F40="","",[3]AST!F40) -> 96226.217 | J53: =+IF([3]AST!G40="","",[3]AST!G40) -> 59068 | K53: =+IF([3]AST!H40="","",[3]AST!H40) -> 1834.8446 | L53: =+IF([3]AST!I40="","",[3]AST!I40) -> 63.928958 | M53: =+IF([3]AST!J40="","",[3]AST!J40) -> 310456.21 | N53: =+'[1]Trim CM INICIAL_ECM'!J42 -> 93.804639 | P53: 200403
A54: =VALUE("1/"&C54&"/"&B54) -> 35886 | B54: =LEFT(D54,4) -> 1998 | C54: 4 | D54: 199804 | E54: =+IF([3]AST!B41="","",[3]AST!B41) -> 311097.95 | F54: =+IF([3]AST!C41="","",[3]AST!C41) | G54: =+IF([3]AST!D41="","",[3]AST!D41) | H54: =+IF([3]AST!E41="","",[3]AST!E41) -> 105.46682 | I54: =+IF([3]AST!F41="","",[3]AST!F41) -> 122057.35 | J54: =+IF([3]AST!G41="","",[3]AST!G41) -> 48369 | K54: =+IF([3]AST!H41="","",[3]AST!H41) -> 1150.2923 | L54: =+IF([3]AST!I41="","",[3]AST!I41) -> 64.120745 | M54: =+IF([3]AST!J41="","",[3]AST!J41) -> 311097.95 | N54: =+'[1]Trim CM INICIAL_ECM'!J43 -> 94.47041 | P54: 200404
A55: =VALUE("1/"&C55&"/"&B55) -> 35916 | B55: =LEFT(D55,4) -> 1998 | C55: 5 | D55: 199805 | E55: =+IF([3]AST!B42="","",[3]AST!B42) -> 313942.39 | F55: =+IF([3]AST!C42="","",[3]AST!C42) | G55: =+IF([3]AST!D42="","",[3]AST!D42) | H55: =+IF([3]AST!E42="","",[3]AST!E42) -> 110.90989 | I55: =+IF([3]AST!F42="","",[3]AST!F42) -> 136804.95 | J55: =+IF([3]AST!G42="","",[3]AST!G42) -> 45363 | K55: =+IF([3]AST!H42="","",[3]AST!H42) -> 1310.4287 | L55: =+IF([3]AST!I42="","",[3]AST!I42) -> 64.248986 | M55: =+IF([3]AST!J42="","",[3]AST!J42) -> 313942.39 | N55: =+'[1]Trim CM INICIAL_ECM'!J44 -> 95.314485 | P55: 200501
A56: =VALUE("1/"&C56&"/"&B56) -> 35947 | B56: =LEFT(D56,4) -> 1998 | C56: 6 | D56: 199806 | E56: =+IF([3]AST!B43="","",[3]AST!B43) -> 318528.13 | F56: =+IF([3]AST!C43="","",[3]AST!C43) | G56: =+IF([3]AST!D43="","",[3]AST!D43) | H56: =+IF([3]AST!E43="","",[3]AST!E43) -> 113.47727 | I56: =+IF([3]AST!F43="","",[3]AST!F43) -> 140448.43 | J56: =+IF([3]AST!G43="","",[3]AST!G43) -> 48107 | K56: =+IF([3]AST!H43="","",[3]AST!H43) -> 1528.0185 | L56: =+IF([3]AST!I43="","",[3]AST!I43) -> 64.248986 | M56: =+IF([3]AST!J43="","",[3]AST!J43) -> 318528.13 | N56: =+'[1]Trim CM INICIAL_ECM'!J45 -> 96.160515 | P56: 200502
A57: =VALUE("1/"&C57&"/"&B57) -> 35977 | B57: =LEFT(D57,4) -> 1998 | C57: 7 | D57: 199807 | E57: =+IF([3]AST!B44="","",[3]AST!B44) -> 321078.71 | F57: =+IF([3]AST!C44="","",[3]AST!C44) | G57: =+IF([3]AST!D44="","",[3]AST!D44) | H57: =+IF([3]AST!E44="","",[3]AST!E44) -> 109.061 | I57: =+IF([3]AST!F44="","",[3]AST!F44) -> 249567.3 | J57: =+IF([3]AST!G44="","",[3]AST!G44) -> 52128 | K57: =+IF([3]AST!H44="","",[3]AST!H44) -> 1367.8821 | L57: =+IF([3]AST!I44="","",[3]AST!I44) -> 64.377484 | M57: =+IF([3]AST!J44="","",[3]AST!J44) -> 321078.71 | N57: =+'[1]Trim CM INICIAL_ECM'!J46 -> 97.081208 | P57: 200503
...

Sheet BAL
D1: Acrónimo | E1: AFI | F1: IAS | G1: ICM | H1: IPI | I1: PER | J1: GAS | K1: HIP | L1: IPC | M1: AFIE | N1: PIB | O1: PIB_CCAA
D2: SA | E2: 0 | F2: 0 | G2: 0 | H2: 0 | I2: 0 | J2: 0 | K2: 0 | L2: 0 | M2: 0 | N2: 0 | O2: 0
D3: DEF | E3: 1 | F3: 1 | G3: 1 | H3: 1 | I3: 1 | J3: 1 | K3: 1 | L3: 1 | M3: 1 | N3: 1 | O3: 1
D4: Serie | E4: afiliados | F4: creditos | G4: depositos | H4: consumo productos petro | I4: hipotecas | J4: indice actividad serviciios | K4: indice comercio al por menor | L4: indice comercio al por menor | M4: indice comercio al por menor | N4: PIB ESPAÑA | O4: PIB ccaa
D5: Enlaces y Deflactores
D6: Fecha INI MOD | E6: 34700 | F6: 34700 | G6: 34700 | H6: 34731 | I6: 34759 | J6: 34790 | K6: 34820 | L6: 34851 | M6: 34881 | N6: 34973 | O6: 35004
D7: Cod | E7: SC | F7: 190000m | G7: 229000cc.d | H7: 229000cc.d | I7: 229000cc.d | J7: 229000cc.d | K7: 229000cc.d | L7: 229000cc.d | M7: 229000cc.d | N7: 229000cc.d | O7: 229000cc.d
D8: Año | E8: 1995 | F8: 2005 | G8: 2001 | H8: 1995 | I8: 1995 | J8: 1997 | K8: 1995 | L8: 1995 | M8: 1995 | N8: 1995 | O8: 2000
D9: Freq | E9: 12 | F9: 12 | G9: 12 | H9: 12 | I9: 12 | J9: 12 | K9: 12 | L9: 12 | M9: 12 | N9: 4 | O9: 1
D10: Mes INI | E10: 8 | F10: 1 | G10: 1 | H10: 1 | I10: 1 | J10: 1 | K10: 1 | L10: 1 | M10: 1 | N10: 1 | O10: 0
D11: type | E11: 6 | F11: 6 | G11: 6 | H11: 6 | I11: 6 | J11: 6 | K11: 6 | L11: 6 | M11: 6 | N11: 2 | O11: 1
D12: dlg | E12: 1 | F12: 1 | G12: 1 | H12: 1 | I12: 1 | J12: 1 | K12: 1 | L12: 1 | M12: 1 | N12: 1 | O12: 1
D13: selector | E13: =+AND!E13 -> 1 | F13: =+AND!F13 -> 1 | G13: =+AND!G13 -> 1 | H13: =+AND!H13 -> 1 | I13: =+AND!I13 -> 1 | J13: =+AND!J13 -> 1 | K13: =+AND!K13 -> 1 | L13: =+AND!L13 -> 1 | ... O13: =+AND!O13 -> 1
A14: Posición de outlier---> | D14: outliers | E14: 0 | F14: 0 | G14: 0 | H14: 0 | I14: 0 | J14: 0 | K14: 0 | L14: 0 | M14: 0 | N14: 0 | O14: 0
A15: =VALUE("1/"&C15&"/"&B15) -> 34700 | B15: =LEFT(D15,4) -> 1995 | C15: 1 | D15: 199501 | E15: =+IF([3]BAL!B2="","",[3]BAL!B2) -> 239058.15 | F15: =+IF([3]BAL!C2="","",[3]BAL!C2) | G15: =+IF([3]BAL!D2="","",[3]BAL!D2) | H15: =+IF([3]BAL!E2="","",[3]BAL!E2) -> 142.71337 | I15: =+IF([3]BAL!F2="","",[3]BAL!F2) -> 1508102.7 | J15: =+IF([3]BAL!G2="","",[3]BAL!G2) | K15: =+IF([3]BAL!H2="","",[3]BAL!H2) -> 864.04067 | L15: =+IF([3]BAL!I2="","",[3]BAL!I2) -> 56.38965 | M15: =+IF([3]BAL!J2="","",[3]BAL!J2) -> 239058.15 | N15: =+'[1]Trim CM INICIAL_ECM'!J4 -> 67.016017 | O15: =+[2]anu!B2 -> 84.237632 | P15: 199501 | Q15: 2000
A16: =VALUE("1/"&C16&"/"&B16) -> 34731 | B16: =LEFT(D16,4) -> 1995 | C16: 2 | D16: 199502 | E16: =+IF([3]BAL!B3="","",[3]BAL!B3) -> 243586.82 | F16: =+IF([3]BAL!C3="","",[3]BAL!C3) | G16: =+IF([3]BAL!D3="","",[3]BAL!D3) | H16: =+IF([3]BAL!E3="","",[3]BAL!E3) -> 135.69756 | I16: =+IF([3]BAL!F3="","",[3]BAL!F3) -> 2148542.3 | J16: =+IF([3]BAL!G3="","",[3]BAL!G3) | K16: =+IF([3]BAL!H3="","",[3]BAL!H3) -> 670.70813 | L16: =+IF([3]BAL!I3="","",[3]BAL!I3) -> 56.671599 | M16: =+IF([3]BAL!J3="","",[3]BAL!J3) -> 243586.82 | N16: =+'[1]Trim CM INICIAL_ECM'!J5 -> 67.457788 | O16: =+[2]anu!B3 -> 87.471178 | P16: 199502 | Q16: =+Q15+1 -> 2001
A17: =VALUE("1/"&C17&"/"&B17) -> 34759 | B17: =LEFT(D17,4) -> 1995 | C17: 3 | D17: 199503 | E17: =+IF([3]BAL!B4="","",[3]BAL!B4) -> 256432.9 | F17: =+IF([3]BAL!C4="","",[3]BAL!C4) | G17: =+IF([3]BAL!D4="","",[3]BAL!D4) | H17: =+IF([3]BAL!E4="","",[3]BAL!E4) -> 155.10389 | I17: =+IF([3]BAL!F4="","",[3]BAL!F4) -> 2828871.6 | J17: =+IF([3]BAL!G4="","",[3]BAL!G4) | K17: =+IF([3]BAL!H4="","",[3]BAL!H4) -> 825.55742 | L17: =+IF([3]BAL!I4="","",[3]BAL!I4) -> 57.011628 | M17: =+IF([3]BAL!J4="","",[3]BAL!J4) -> 256432.9 | N17: =+'[1]Trim CM INICIAL_ECM'!J6 -> 67.756519 | O17: =+[2]anu!B4 -> 90.579301 | P17: 199503 | Q17: =+Q16+1 -> 2002
A18: =VALUE("1/"&C18&"/"&B18) -> 34790 | B18: =LEFT(D18,4) -> 1995 | C18: 4 | D18: 199504 | E18: =+IF([3]BAL!B5="","",[3]BAL!B5) -> 271220.48 | F18: =+IF([3]BAL!C5="","",[3]BAL!C5) | G18: =+IF([3]BAL!D5="","",[3]BAL!D5) | H18: =+IF([3]BAL!E5="","",[3]BAL!E5) -> 134.80104 | I18: =+IF([3]BAL!F5="","",[3]BAL!F5) -> 3973753.8 | J18: =+IF([3]BAL!G5="","",[3]BAL!G5) | K18: =+IF([3]BAL!H5="","",[3]BAL!H5) -> 574.5 | L18: =+IF([3]BAL!I5="","",[3]BAL!I5) -> 57.41071 | M18: =+IF([3]BAL!J5="","",[3]BAL!J5) -> 271220.48 | N18: =+'[1]Trim CM INICIAL_ECM'!J7 -> 68.269558 | O18: =+[2]anu!B5 -> 94.186666 | P18: 199504 | Q18: =+Q17+1 -> 2003
A19: =VALUE("1/"&C19&"/"&B19) -> 34820 | B19: =LEFT(D19,4) -> 1995 | C19: 5 | D19: 199505 | E19: =+IF([3]BAL!B6="","",[3]BAL!B6) -> 304036.46 | F19: =+IF([3]BAL!C6="","",[3]BAL!C6) | G19: =+IF([3]BAL!D6="","",[3]BAL!D6) | H19: =+IF([3]BAL!E6="","",[3]BAL!E6) -> 147.19203 | I19: =+IF([3]BAL!F6="","",[3]BAL!F6) -> 8789730.2 | J19: =+IF([3]BAL!G6="","",[3]BAL!G6) | K19: =+IF([3]BAL!H6="","",[3]BAL!H6) -> 1239.7105 | L19: =+IF([3]BAL!I6="","",[3]BAL!I6) -> 57.525531 | M19: =+IF([3]BAL!J6="","",[3]BAL!J6) -> 304036.46 | N19: =+'[1]Trim CM INICIAL_ECM'!J8 -> 68.661842 | O19: =+[2]anu!B6 -> 97.421534 | P19: 199601 | Q19: =+Q18+1 -> 2004
